<?xml version="1.0" ?>
<!-- =================================================================================== -->
<!-- |    This document was autogenerated by xacro from robot.xacro                    | -->
<!-- |    EDITING THIS FILE BY HAND IS NOT RECOMMENDED                                 | -->
<!-- =================================================================================== -->
<robot name="robot">
  <!-- ros_control plugin -->
  <gazebo>
    <plugin filename="libgazebo_ros_control.so" name="gazebo_ros_control">
      <robotNamespace>/robot</robotNamespace>
      <robotSimType>gazebo_ros_control/DefaultRobotHWSim</robotSimType>
    </plugin>
  </gazebo>
  <link name="world"/>
  <joint name="base_joint" type="fixed">
    <parent link="world"/>
    <child link="base_link"/>
  </joint>
  <link name="base_link">
    <visual>
      <origin rpy="0 0 0" xyz="0 0 0.05"/>
      <geometry>
        <cylinder length="0.1" radius="0.15"/>
      </geometry>
    </visual>
    <collision>
      <origin rpy="0 0 0" xyz="0 0 0.05"/>
      <geometry>
        <cylinder length="0.1" radius="0.15"/>
      </geometry>
    </collision>
    <inertial>
      <origin rpy="0 0 0" xyz="0 0 0.05"/>
      <mass value="1"/>
      <inertia ixx="0.0064583333333333316" ixy="0.0" ixz="0.0" iyy="0.0064583333333333316" iyz="0.0" izz="0.01125"/>
    </inertial>
  </link>
  <joint name="joint1" type="continuous">
    <!-- <safety_controller k_position="100.0" k_velocity="40.0" soft_lower_limit="-2.8973" soft_upper_limit="2.8973"/> -->
    <origin rpy="0 0 0" xyz="0 0 0.1"/>
    <parent link="base_link"/>
    <child link="link0"/>
    <axis xyz="0 0 1"/>
    <dynamics damping="0.7"/>
  </joint>
  <link name="link0">
    <visual>
      <origin rpy="0 0 0" xyz="0 0 0.5"/>
      <geometry>
        <cylinder length="1" radius="0.075"/>
      </geometry>
    </visual>
    <collision>
      <origin rpy="0 0 0" xyz="0 0 0.5"/>
      <geometry>
        <cylinder length="1" radius="0.075"/>
      </geometry>
    </collision>
    <inertial>
      <origin rpy="0 0 0" xyz="0 0 0.5"/>
      <mass value="1"/>
      <inertia ixx="0.08473958333333333" ixy="0.0" ixz="0.0" iyy="0.08473958333333333" iyz="0.0" izz="0.0028125"/>
    </inertial>
  </link>
  <joint name="fixedjoint0" type="fixed">
    =
      
    <origin rpy="0 0 0" xyz="0 0 1"/>
    <parent link="link0"/>
    <child link="link1"/>
    <axis xyz="0 0 1"/>
    =
    
  </joint>
  <link name="link1">
    <visual>
      <origin rpy="1.57 0 0" xyz="0 0.425 0"/>
      <geometry>
        <cylinder length="1" radius="0.075"/>
      </geometry>
    </visual>
    <collision>
      <origin rpy="1.57 0 0" xyz="0 0.425 0"/>
      <geometry>
        <cylinder length="1" radius="0.075"/>
      </geometry>
    </collision>
    <inertial>
      <origin rpy="1.57 0 0" xyz="0 0.425 0"/>
      <mass value="1"/>
      <inertia ixx="0.3333333333333333" ixy="0.0" ixz="0.0" iyy="1" iyz="0.0" izz="0.3333333333333333"/>
    </inertial>
  </link>
  <joint name="joint2" type="revolute">
    <!-- <safety_controller k_position="100.0" k_velocity="40.0" soft_lower_limit="-2.8973" soft_upper_limit="2.8973"/> -->
    <origin rpy="0 0 0" xyz="0 0.925 0"/>
    <parent link="link1"/>
    <child link="joint2link"/>
    <axis xyz="0 0 1"/>
    <limit effort="1000" lower="-2.8973" upper="2.8973" velocity="2.1750"/>
  </joint>
  <link name="joint2link">
    <visual>
      <origin rpy="0 0 0" xyz="0 0 0"/>
      <geometry>
        <cylinder length="0.15" radius="0.075"/>
      </geometry>
    </visual>
    <collision>
      <origin rpy="0 0 0" xyz="0 0 0"/>
      <geometry>
        <cylinder length="0.15" radius="0.075"/>
      </geometry>
    </collision>
    <inertial>
      <origin rpy="0 0 0" xyz="0 0 0"/>
      <mass value="1"/>
      <inertia ixx="0.0032812499999999994" ixy="0.0" ixz="0.0" iyy="0.0032812499999999994" iyz="0.0" izz="0.0028125"/>
    </inertial>
  </link>
  <joint name="fixedjoint1" type="fixed">
    <!-- <safety_controller k_position="100.0" k_velocity="40.0" soft_lower_limit="-2.8973" soft_upper_limit="2.8973"/> -->
    <origin rpy="0 0 0" xyz="0 0 0"/>
    <parent link="joint2link"/>
    <child link="link2"/>
  </joint>
  <link name="link2">
    <visual>
      <origin rpy="1.57 0 0" xyz="0 0.5 0"/>
      <geometry>
        <cylinder length="1" radius="0.075"/>
      </geometry>
    </visual>
    <collision>
      <origin rpy="1.57 0 0" xyz="0 0.5 0"/>
      <geometry>
        <cylinder length="1" radius="0.075"/>
      </geometry>
    </collision>
    <inertial>
      <origin rpy="1.57 0 0" xyz="0 0.5 0"/>
      <mass value="1"/>
      <inertia ixx="0.3333333333333333" ixy="0.0" ixz="0.0" iyy="1" iyz="0.0" izz="0.3333333333333333"/>
    </inertial>
  </link>
  <joint name="fixedjoint2" type="fixed">
    <!-- <safety_controller k_position="100.0" k_velocity="40.0" soft_lower_limit="-2.8973" soft_upper_limit="2.8973"/> -->
    <origin rpy="0 0 0" xyz="0 1 0"/>
    <parent link="link2"/>
    <child link="joint3link"/>
  </joint>
  <link name="joint3link">
    <visual>
      <origin rpy="0 0 0" xyz="0 0 0"/>
      <geometry>
        <cylinder length="0.15" radius="0.075"/>
      </geometry>
    </visual>
    <collision>
      <origin rpy="0 0 0" xyz="0 0 0"/>
      <geometry>
        <cylinder length="0.15" radius="0.075"/>
      </geometry>
    </collision>
    <inertial>
      <origin rpy="0 0 0" xyz="0 0 0"/>
      <mass value="1"/>
      <inertia ixx="0.0032812499999999994" ixy="0.0" ixz="0.0" iyy="0.0032812499999999994" iyz="0.0" izz="0.0028125"/>
    </inertial>
  </link>
  <joint name="joint3" type="prismatic">
    <!-- <safety_controller k_position="100.0" k_velocity="40.0" soft_lower_limit="-2.8973" soft_upper_limit="2.8973"/> -->
    <origin rpy="0 0 0" xyz="0 0 0"/>
    <parent link="joint3link"/>
    <child link="link3"/>
    <axis xyz="0 0 -1"/>
    <limit effort="1000" lower="-0.3" upper="0.3" velocity="0.1"/>
  </joint>
  <gazebo reference="joint3">
    <implicitSpringDamper>1</implicitSpringDamper>
  </gazebo>
  <link name="link3">
    <visual>
      <origin rpy="0 0 0" xyz="0 0 0"/>
      <geometry>
        <cylinder length="1" radius="0.0375"/>
      </geometry>
    </visual>
    <collision>
      <origin rpy="0 0 0" xyz="0 0 0"/>
      <geometry>
        <cylinder length="1" radius="0.0375"/>
      </geometry>
    </collision>
    <inertial>
      <origin rpy="0 0 0" xyz="0 0 0"/>
      <mass value="1"/>
      <inertia ixx="0.08368489583333333" ixy="0.0" ixz="0.0" iyy="0.08368489583333333" iyz="0.0" izz="0.000703125"/>
    </inertial>
  </link>
  <!-- <gazebo reference="link3">
      <kp>10000000.0</kp>
      <kd>1.0</kd>
      <mu1>100000.0</mu1>
      <mu2>100000.0</mu2>
      <minDepth>0.001</minDepth>
    </gazebo> -->
  <transmission name="tran1">
    <type>transmission_interface/SimpleTransmission</type>
    <joint name="joint1">
      <hardwareInterface>hardware_interface/VelocityJointInterface</hardwareInterface>
    </joint>
    <actuator name="motor1">
      <hardwareInterface>hardware_interface/VelocityJointInterface</hardwareInterface>
      <mechanicalReduction>1</mechanicalReduction>
    </actuator>
  </transmission>
  <transmission name="tran2">
    <type>transmission_interface/SimpleTransmission</type>
    <joint name="joint2">
      <hardwareInterface>hardware_interface/VelocityJointInterface</hardwareInterface>
    </joint>
    <actuator name="motor2">
      <hardwareInterface>hardware_interface/VelocityJointInterface</hardwareInterface>
      <mechanicalReduction>1</mechanicalReduction>
    </actuator>
  </transmission>
  <transmission name="tran3">
    <type>transmission_interface/SimpleTransmission</type>
    <joint name="joint3">
      <hardwareInterface>hardware_interface/VelocityJointInterface</hardwareInterface>
    </joint>
    <actuator name="motor3">
      <mechanicalReduction>1</mechanicalReduction>
    </actuator>
  </transmission>
  <gazebo reference="joint3">
    <implicitSpringDamper>1</implicitSpringDamper>
  </gazebo>
</robot>
