<?xml version="1.0" ?>
<!-- =================================================================================== -->
<!-- |    This document was autogenerated by xacro from robot.xacro                    | -->
<!-- |    EDITING THIS FILE BY HAND IS NOT RECOMMENDED                                 | -->
<!-- =================================================================================== -->
<robot name="robot">
  <link name="world"/>
  <joint name="base_joint" type="fixed">
    <parent link="world"/>
    <child link="link0"/>
  </joint>
  <link name="link0">
    <visual>
      <origin rpy="0 0 0" xyz="0 0 0.5"/>
      <geometry>
        <cylinder length="1" radius="0.1"/>
      </geometry>
      <material name="orange"/>
    </visual>
    <collision>
      <origin rpy="0 0 0" xyz="0 0 0.5"/>
      <geometry>
        <cylinder length="1" radius="0.1"/>
      </geometry>
    </collision>
    <inertial>
      <origin rpy="0 0 0" xyz="0 0 0.5"/>
      <mass value="1"/>
      <inertia ixx="0" ixy="0.0" ixz="0.0" iyy="0" iyz="0.0" izz="0"/>
    </inertial>
  </link>
  <link name="link1">
    <visual>
      <origin rpy="1.57 0 0" xyz="0 0.5 0"/>
      <geometry>
        <cylinder length="1" radius="0.1"/>
      </geometry>
      <material name="orange"/>
    </visual>
    <collision>
      <origin rpy="1.57 0 0" xyz="0 0.5 0"/>
      <geometry>
        <cylinder length="1" radius="0.1"/>
      </geometry>
    </collision>
    <inertial>
      <origin rpy="1.57 0 0" xyz="0 0.5 0"/>
      <mass value="1"/>
      <inertia ixx="0" ixy="0.0" ixz="0.0" iyy="0" iyz="0.0" izz="0"/>
    </inertial>
  </link>
  <link name="link2">
    <visual>
      <origin rpy="1.57 0 0" xyz="0 0.5 1"/>
      <geometry>
        <cylinder length="1" radius="0.1"/>
      </geometry>
      <material name="orange"/>
    </visual>
    <collision>
      <origin rpy="1.57 0 0" xyz="0 0.5 1"/>
      <geometry>
        <cylinder length="1" radius="0.1"/>
      </geometry>
    </collision>
    <inertial>
      <origin rpy="1.57 0 0" xyz="0 0.5 1"/>
      <mass value="1"/>
      <inertia ixx="0" ixy="0.0" ixz="0.0" iyy="0" iyz="0.0" izz="0"/>
    </inertial>
  </link>
  <joint name="joint1" type="revolute">
    <!-- <safety_controller k_position="100.0" k_velocity="40.0" soft_lower_limit="-2.8973" soft_upper_limit="2.8973"/> -->
    <origin rpy="0 0 0" xyz="0 0 1"/>
    <parent link="link0"/>
    <child link="link1"/>
    <axis xyz="0 0 1"/>
    <limit effort="87" lower="-2.8973" upper="2.8973" velocity="2.1750"/>
  </joint>
  <joint name="joint2" type="revolute">
    <!-- <safety_controller k_position="100.0" k_velocity="40.0" soft_lower_limit="-2.8973" soft_upper_limit="2.8973"/> -->
    <origin rpy="0 0 0" xyz="0 0.5 1"/>
    <parent link="link1"/>
    <child link="link2"/>
    <axis xyz="0 0 1"/>
    <limit effort="87" lower="-2.8973" upper="2.8973" velocity="2.1750"/>
  </joint>
</robot>
